<?xml version="1.0" encoding="utf-8"?>
<!-- This URDF was automatically created by SolidWorks to URDF Exporter! Originally created by Stephen Brawner (brawner@gmail.com) 
     Commit Version: 1.6.0-1-g15f4949  Build Version: 1.6.7594.29634
     For more information, please see http://wiki.ros.org/sw_urdf_exporter -->
<robot
  name="proj1_assembly">
  <link name="dummy_link">
  </link>
  <joint name="dummy_joint" type="fixed">
    <parent link="dummy_link"/>
    <child link="chasis"/>
  </joint>
  <link
    name="chasis">
    <inertial>
      <origin
        xyz="-0.05109 -9.5143E-17 0.036183"
        rpy="0 0 0" />
      <mass
        value="30.536" />
      <inertia
        ixx="0.56323"
        ixy="-3.1084E-16"
        ixz="-0.00072627"
        iyy="2.0786"
        iyz="3.8259E-17"
        izz="2.6033" />
    </inertial>
    <visual>
      <origin
        xyz="0 0 0"
        rpy="0 0 0" />
      <geometry>
        <mesh
          filename="package://proj1_assembly/meshes/chasis.STL" />
      </geometry>
      <material
        name="">
        <color
          rgba="0.79216 0.81961 0.93333 1" />
      </material>
    </visual>
    <collision>
      <origin
        xyz="0 0 0"
        rpy="0 0 0" />
      <geometry>
        <mesh
          filename="package://proj1_assembly/meshes/chasis.STL" />
      </geometry>
    </collision>
  </link>
  <link
    name="front_wheel">
    <inertial>
      <origin
        xyz="0 2.77555756156289E-17 0.00635000000000007"
        rpy="0 0 0" />
      <mass
        value="2.90870361301128" />
      <inertia
        ixx="0.0105118190507943"
        ixy="-4.33680868994202E-19"
        ixz="4.00578241400834E-19"
        iyy="0.0105118190507943"
        iyz="1.73053538283402E-19"
        izz="0.0129886683607583" />
    </inertial>
    <visual>
      <origin
        xyz="0 0 0"
        rpy="0 0 0" />
      <geometry>
        <mesh
          filename="package://proj1_assembly/meshes/front_wheel.STL" />
      </geometry>
      <material
        name="">
        <color
          rgba="0.792156862745098 0.819607843137255 0.933333333333333 1" />
      </material>
    </visual>
    <collision>
      <origin
        xyz="0 0 0"
        rpy="0 0 0" />
      <geometry>
        <mesh
          filename="package://proj1_assembly/meshes/front_wheel.STL" />
      </geometry>
    </collision>
  </link>
  <joint
    name="front_joint"
    type="continuous">
    <origin
      xyz="0.1905 0 -0.0381"
      rpy="-1.5708 1.1406 -3.1416" />
    <parent
      link="chasis" />
    <child
      link="front_wheel" />
    <axis
      xyz="0 0 1" />
  </joint>
  <link
    name="back_left_wheel">
    <inertial>
      <origin
        xyz="5.5511E-17 1.3878E-17 -0.1081"
        rpy="0 0 0" />
      <mass
        value="2.6899" />
      <inertia
        ixx="0.0089389"
        ixy="4.3368E-19"
        ixz="3.7838E-19"
        iyy="0.0089389"
        iyz="2.1236E-19"
        izz="0.012871" />
    </inertial>
    <visual>
      <origin
        xyz="0 0 0"
        rpy="0 0 0" />
      <geometry>
        <mesh
          filename="package://proj1_assembly/meshes/back_left_wheel.STL" />
      </geometry>
      <material
        name="">
        <color
          rgba="0.79216 0.81961 0.93333 1" />
      </material>
    </visual>
    <collision>
      <origin
        xyz="0 0 0"
        rpy="0 0 0" />
      <geometry>
        <mesh
          filename="package://proj1_assembly/meshes/back_left_wheel.STL" />
      </geometry>
    </collision>
  </link>
  <joint
    name="back_left_joint"
    type="continuous">
    <origin
      xyz="-0.3175 0.1524 -0.0381"
      rpy="1.5708 0.091451 0" />
    <parent
      link="chasis" />
    <child
      link="back_left_wheel" />
    <axis
      xyz="0 0 1" />
  </joint>
  <link
    name="back_right_wheel">
    <inertial>
      <origin
        xyz="5.5511E-17 -2.7756E-17 -0.1081"
        rpy="0 0 0" />
      <mass
        value="2.6899" />
      <inertia
        ixx="0.0089389"
        ixy="4.3368E-19"
        ixz="-1.1129E-18"
        iyy="0.0089389"
        iyz="1.3881E-18"
        izz="0.012871" />
    </inertial>
    <visual>
      <origin
        xyz="0 0 0"
        rpy="0 0 0" />
      <geometry>
        <mesh
          filename="package://proj1_assembly/meshes/back_right_wheel.STL" />
      </geometry>
      <material
        name="">
        <color
          rgba="0.79216 0.81961 0.93333 1" />
      </material>
    </visual>
    <collision>
      <origin
        xyz="0 0 0"
        rpy="0 0 0" />
      <geometry>
        <mesh
          filename="package://proj1_assembly/meshes/back_right_wheel.STL" />
      </geometry>
    </collision>
  </link>
  <joint
    name="back_right_joint"
    type="continuous">
    <origin
      xyz="-0.3175 -0.1524 -0.0381"
      rpy="-1.5708 0.7098 0" />
    <parent
      link="chasis" />
    <child
      link="back_right_wheel" />
    <axis
      xyz="0 0 1" />
  </joint>
  <transmission name="front_wheel">
    <type>transmission_interface/SimpleTransmission</type>
    <joint name="front_joint">
      <hardwareInterface>hardware_interface/EffortJointInterface</hardwareInterface>
    </joint>
    <actuator name="motor_front">
      <hardwareInterface>hardware_interface/EffortJointInterface</hardwareInterface>
      <mechanicalReduction>1</mechanicalReduction>
    </actuator>
  </transmission>
  <transmission name="right_wheel">
    <type>transmission_interface/SimpleTransmission</type>
    <joint name="back_right_joint">
      <hardwareInterface>hardware_interface/EffortJointInterface</hardwareInterface>
    </joint>
    <actuator name="motor_right">
      <hardwareInterface>hardware_interface/EffortJointInterface</hardwareInterface>
      <mechanicalReduction>1</mechanicalReduction>
    </actuator>
  </transmission>
  <transmission name="left_wheel">
    <type>transmission_interface/SimpleTransmission</type>
    <joint name="back_left_joint">
      <hardwareInterface>hardware_interface/EffortJointInterface</hardwareInterface>
    </joint>
    <actuator name="motor_left">
      <hardwareInterface>hardware_interface/EffortJointInterface</hardwareInterface>
      <mechanicalReduction>1</mechanicalReduction>
    </actuator>
  </transmission>
</robot>
