<?xml version="1.0" ?>
<!-- =================================================================================== -->
<!-- |    This document was autogenerated by xacro from my_robot_integration.urdf.xacro | -->
<!-- |    EDITING THIS FILE BY HAND IS NOT RECOMMENDED                                 | -->
<!-- =================================================================================== -->
<!-- proj1_assembly -->
<robot name="proj1_assembly">
  <link name="dummy_link">
  </link>
  <joint name="dummy_joint" type="fixed">
    <parent link="dummy_link"/>
    <child link="chasis"/>
  </joint>
  <link name="chasis">
    <inertial>
      <origin rpy="0 0 0" xyz="-0.05109 -9.5143E-17 0.036183"/>
      <mass value="30.536"/>
      <inertia ixx="0.56323" ixy="-3.1084E-16" ixz="-0.00072627" iyy="2.0786" iyz="3.8259E-17" izz="2.6033"/>
    </inertial>
    <visual>
      <origin rpy="0 0 0" xyz="0 0 0"/>
      <geometry>
        <mesh filename="package://proj1_assembly/meshes/chasis.STL"/>
      </geometry>
      <material name="">
        <color rgba="0.79216 0.81961 0.93333 1"/>
      </material>
    </visual>
    <collision>
      <origin rpy="0 0 0" xyz="0 0 0"/>
      <geometry>
        <mesh filename="package://proj1_assembly/meshes/chasis.STL"/>
      </geometry>
    </collision>
  </link>
  <link name="front_wheel">
    <inertial>
      <origin rpy="0 0 0" xyz="0 2.77555756156289E-17 0.00635000000000007"/>
      <mass value="2.90870361301128"/>
      <inertia ixx="0.0105118190507943" ixy="-4.33680868994202E-19" ixz="4.00578241400834E-19" iyy="0.0105118190507943" iyz="1.73053538283402E-19" izz="0.0129886683607583"/>
    </inertial>
    <visual>
      <origin rpy="0 0 0" xyz="0 0 0"/>
      <geometry>
        <mesh filename="package://proj1_assembly/meshes/front_wheel.STL"/>
      </geometry>
      <material name="">
        <color rgba="0.792156862745098 0.819607843137255 0.933333333333333 1"/>
      </material>
    </visual>
    <collision>
      <origin rpy="0 0 0" xyz="0 0 0"/>
      <geometry>
        <mesh filename="package://proj1_assembly/meshes/front_wheel.STL"/>
      </geometry>
    </collision>
  </link>
  <joint name="front_joint" type="continuous">
    <origin rpy="-1.5708 1.1406 -3.1416" xyz="0.1905 0 -0.0381"/>
    <parent link="chasis"/>
    <child link="front_wheel"/>
    <axis xyz="0 0 1"/>
  </joint>
  <link name="back_left_wheel">
    <inertial>
      <origin rpy="0 0 0" xyz="5.5511E-17 1.3878E-17 -0.1081"/>
      <mass value="2.6899"/>
      <inertia ixx="0.0089389" ixy="4.3368E-19" ixz="3.7838E-19" iyy="0.0089389" iyz="2.1236E-19" izz="0.012871"/>
    </inertial>
    <visual>
      <origin rpy="0 0 0" xyz="0 0 0"/>
      <geometry>
        <mesh filename="package://proj1_assembly/meshes/back_left_wheel.STL"/>
      </geometry>
      <material name="">
        <color rgba="0.79216 0.81961 0.93333 1"/>
      </material>
    </visual>
    <collision>
      <origin rpy="0 0 0" xyz="0 0 0"/>
      <geometry>
        <mesh filename="package://proj1_assembly/meshes/back_left_wheel.STL"/>
      </geometry>
    </collision>
  </link>
  <joint name="back_left_joint" type="continuous">
    <origin rpy="1.5708 0.091451 0" xyz="-0.3175 0.1524 -0.0381"/>
    <parent link="chasis"/>
    <child link="back_left_wheel"/>
    <axis xyz="0 0 1"/>
  </joint>
  <link name="back_right_wheel">
    <inertial>
      <origin rpy="0 0 0" xyz="5.5511E-17 -2.7756E-17 -0.1081"/>
      <mass value="2.6899"/>
      <inertia ixx="0.0089389" ixy="4.3368E-19" ixz="-1.1129E-18" iyy="0.0089389" iyz="1.3881E-18" izz="0.012871"/>
    </inertial>
    <visual>
      <origin rpy="0 0 0" xyz="0 0 0"/>
      <geometry>
        <mesh filename="package://proj1_assembly/meshes/back_right_wheel.STL"/>
      </geometry>
      <material name="">
        <color rgba="0.79216 0.81961 0.93333 1"/>
      </material>
    </visual>
    <collision>
      <origin rpy="0 0 0" xyz="0 0 0"/>
      <geometry>
        <mesh filename="package://proj1_assembly/meshes/back_right_wheel.STL"/>
      </geometry>
    </collision>
  </link>
  <joint name="back_right_joint" type="continuous">
    <origin rpy="-1.5708 0.7098 0" xyz="-0.3175 -0.1524 -0.0381"/>
    <parent link="chasis"/>
    <child link="back_right_wheel"/>
    <axis xyz="0 0 1"/>
  </joint>
  <transmission name="front_wheel">
    <type>transmission_interface/SimpleTransmission</type>
    <joint name="front_joint">
      <hardwareInterface>hardware_interface/EffortJointInterface</hardwareInterface>
    </joint>
    <actuator name="motor_front">
      <hardwareInterface>hardware_interface/EffortJointInterface</hardwareInterface>
      <mechanicalReduction>1</mechanicalReduction>
    </actuator>
  </transmission>
  <transmission name="right_wheel">
    <type>transmission_interface/SimpleTransmission</type>
    <joint name="back_right_joint">
      <hardwareInterface>hardware_interface/EffortJointInterface</hardwareInterface>
    </joint>
    <actuator name="motor_right">
      <hardwareInterface>hardware_interface/EffortJointInterface</hardwareInterface>
      <mechanicalReduction>1</mechanicalReduction>
    </actuator>
  </transmission>
  <transmission name="left_wheel">
    <type>transmission_interface/SimpleTransmission</type>
    <joint name="back_left_joint">
      <hardwareInterface>hardware_interface/EffortJointInterface</hardwareInterface>
    </joint>
    <actuator name="motor_left">
      <hardwareInterface>hardware_interface/EffortJointInterface</hardwareInterface>
      <mechanicalReduction>1</mechanicalReduction>
    </actuator>
  </transmission>
  <link name="base_laser">
    <inertial>
      <origin rpy="0 0 0" xyz="-0.00029774 0.0066667 0.00013047"/>
      <mass value="0.15717"/>
      <inertia ixx="6.7885E-05" ixy="-1.3987E-07" ixz="-8.1554E-07" iyy="0.00013173" iyz="-9.0932E-08" izz="7.1972E-05"/>
    </inertial>
    <visual>
      <origin rpy="0 0 0" xyz="0 0 0"/>
      <geometry>
        <mesh filename="package://ydlidar_ros/meshes/ydlidar.dae"/>
      </geometry>
      <material name="">
        <color rgba="0.64706 0.61961 0.58824 1"/>
      </material>
    </visual>
    <collision>
      <origin rpy="0 0 0" xyz="0 0 0"/>
      <geometry>
        <mesh filename="package://ydlidar_ros/meshes/ydlidar.dae"/>
      </geometry>
    </collision>
  </link>
  <link name="laser_frame">
    <inertial>
      <origin rpy="0 0 0" xyz="-0.00036659 0.00064155 -0.00027052"/>
      <mass value="0.25482"/>
      <inertia ixx="8.9194E-05" ixy="1.8116E-07" ixz="3.6435E-08" iyy="0.00018279" iyz="2.423E-07" izz="0.00011103"/>
    </inertial>
    <!--visual>
      <origin
        xyz="0 0 0"
        rpy="0 0 0" />
      <geometry>
        <mesh
          filename="package://ydlidar_ros/meshes/ydlidar.dae" />
      </geometry>
      <material
        name="">
        <color
          rgba="0.64706 0.61961 0.58824 1" />
      </material>
    </visual-->
    <!--collision>
      <origin
        xyz="0 0 0"
        rpy="0 0 0" />
      <geometry>
        <mesh
          filename="package://ydlidar_ros/meshes/ydlidar.dae" />
      </geometry>
    </collision-->
  </link>
  <joint name="laser_joint" type="fixed">
    <origin rpy="0 0 0" xyz="0 0 0.03172"/>
    <parent link="base_laser"/>
    <child link="laser_frame"/>
    <axis xyz="0 0 0"/>
  </joint>
  <!-- Add your gazebo sensors here -->
  <gazebo reference="base_laser">
    <sensor name="head_hokuyo_sensor" type="ray">
      <pose>0 0 0 0 0 0</pose>
      <visualize>false</visualize>
      <update_rate>40</update_rate>
      <ray>
        <scan>
          <horizontal>
            <samples>720</samples>
            <resolution>1</resolution>
            <min_angle>-1.570796</min_angle>
            <max_angle>1.570796</max_angle>
          </horizontal>
        </scan>
        <range>
          <min>0.8</min>
          <max>30.0</max>
          <resolution>0.01</resolution>
        </range>
        <noise>
          <type>gaussian</type>
          <!-- Noise parameters based on published spec for Hokuyo laser
               achieving "+-30mm" accuracy at range < 10m.  A mean of 0.0m and
               stddev of 0.01m will put 99.7% of samples within 0.03m of the true
               reading. -->
          <mean>0.0</mean>
          <stddev>0.01</stddev>
        </noise>
      </ray>
      <plugin filename="libgazebo_ros_laser.so" name="gazebo_ros_head_hokuyo_controller">
        <topicName>/laser/scan</topicName>
        <frameName>laser_frame</frameName>
      </plugin>
    </sensor>
  </gazebo>
  <!--  Gazebo plugin for control here is already added for you -->
  <gazebo>
    <plugin filename="libgazebo_ros_control.so" name="gazebo_ros_control">
      <robotNamespace>/proj1</robotNamespace>
      <robotSimType>gazebo_ros_control/DefaultRobotHWSim</robotSimType>
      <legacyModeNS>true</legacyModeNS>
    </plugin>
  </gazebo>
  <!-- Create a joint between your robot and sensor -->
  <joint name="sensor_joint" type="fixed">
    <parent link="dummy_link"/>
    <child link="base_laser"/>
    <origin xyz="0 0 0.08"/>
  </joint>
</robot>
